<mujoco model="coffeemachine">
    <compiler angle="radian" inertiafromgeom="auto" inertiagrouprange="4 5"/>
    <asset>

        <material name="cm_col" rgba="0.3 0.3 1.0 0.5" shininess="0" specular="0"/>
        <material name="cmred" rgba="0.38 0.19 0.2 1" shininess="1" reflectance=".7" specular=".5"/>
        <material name="cmwhite" rgba=".85 .85 .85 1" shininess="1" reflectance=".7" specular=".5"/>
        <material name="cmgrey" rgba=".65 .65 .65 1" shininess="1" reflectance="1" specular=".5"/>

        <material name="cmblack" rgba=".2 .2 .2 1" shininess="1" reflectance=".7" specular=".5"/>
        <mesh file="meshes/coffeemachine/body1.stl" name="body1"/>
        <mesh file="meshes/coffeemachine/body2.stl" name="body2"/>
        <mesh file="meshes/coffeemachine/button.stl" name="button"/>
        <mesh file="meshes/coffeemachine/mug.stl" name="mug"/>
        <mesh file="meshes/coffeemachine/handle.stl" name="handle"/>
        <mesh file="meshes/coffeemachine/spout.stl" name="spout"/>
        <mesh file="meshes/coffeemachine/spoutconnect.stl" name="spoutconnect"/>
        <mesh file="meshes/coffeemachine/buttonring.stl" name="buttonring"/>
        <mesh file="meshes/coffeemachine/bodypiece1.stl" name="bodypiece1"/>
    </asset>
    <default>

        <default class="cm_base">
            <joint armature="0.001" damping="2" limited="true"/>
            <geom conaffinity="0" contype="0" group="1" type="mesh"/>
            <position ctrllimited="true" ctrlrange="0 1.57"/>
            <default class="cm_viz">
                <geom condim="4" type="mesh"/>
            </default>
            <default class="cm_col">
                <geom conaffinity="1" condim="3" contype="1" group="0" material="cm_col" solimp="0.99 0.99 0.01"
                      solref="0.01 1"/>
            </default>
        </default>
    </default>
    <worldbody>
        <body childclass="cm_base" name="coffeemachine">
            <body name="object">
                <body name="cm_link">
                    <geom material="cmblack" euler="1.57 0 0" pos="0 -0.109 0.135" size="0.009 0.018" type="cylinder" conaffinity="0" contype="0" group="0"/>
                    <geom class="cm_col" pos="0.069 -0.133 0.3" size="0.031 0.05 0.035" type="box" material="cmred"/>
                    <geom class="cm_col" pos="-0.069 -0.133 0.3" size="0.031 0.05 0.035" type="box" material="cmred"/>
                    <geom class="cm_col" pos="0.0 -0.133 0.352" size="0.1 0.05 0.018" type="box" material="cmred"/>
                    <geom class="cm_col" pos="0.0 -0.133 0.248" size="0.1 0.05 0.018" type="box" material="cmred"/>
                    <geom class="cm_col" pos="0 0 0.115" size="0.1 0.098 0.115" type="box" material="cmred"/>
                    <geom class="cm_col" euler="1.57 0 0" pos="0 -0.109 0.135" size="0.009 0.018" type="cylinder" material="cmblack"/>
                    <geom class="cm_col" pos="0.0 -0.141 0.152" size="0.016 0.041" type="cylinder" material="cmblack"/>
                    <geom class="cm_col" pos="0 0 0.3" size="0.1 0.098 0.07" type="box" material="cmred"/>
                    <site name="coffee_goal" pos="0 -.22 0" size="0.01" rgba="1 0 0 1"/>
                </body>
                <body name="cmbutton_1" pos="0 0 0">
                    <geom material="cmgrey" euler="1.57 0 0" pos="0 -0.19 0.3" size="0.03 0.028 0.032" type="cylinder"
                          group="0"/>
                    <joint type="slide" range="0 0.03" axis="0 1 0" name="goal_slidey_1" pos="0 0 0" damping="1.0"/>
                    <site name="buttonStart" pos="0.0 -0.22 0.3" size="0.005" rgba="0 0.8 0 1"/>
                </body>

            </body>
            <site rgba="0 0 0 0" size="0.0005" pos="0 0 -0.08" name="bottom_site"/>
            <site rgba="0 0 0 0" size="0.0005" pos="0 0 0.65" name="top_site"/>
            <site rgba="0 0 0 0" size="0.0005" pos="0.011 0.09 0" name="horizontal_radius_site"/>
        </body>
    </worldbody>
</mujoco>
