<mujoco model="drawer">
    <compiler angle="radian" inertiafromgeom="auto"/>
    <asset>
        <texture name="T_shelf_wood" type="cube" file="textures/wood1.png"/>
        <material name="drawer_col" texture="T_shelf_wood" reflectance="0.7" texrepeat="5 5" texuniform="true"/>
    </asset>
    <default>
        <default class="drawer_col">
            <geom conaffinity="1" condim="3" contype="1" group="0" material="drawer_col" solimp="0.99 0.99 0.01"
                  solref="0.01 1" density="8000"/>
        </default>
    </default>

    <worldbody>
        <body>
            <body name="object">
                <body name="drawer_case1" pos="-0.10 0 0.084">
                    <geom class="drawer_col" pos="-0.09 0 0" size="0.008 0.1 0.084" type="box"/>
                    <geom class="drawer_col" pos="0.09 0 0" size="0.008 0.1 0.084" type="box"/>
                    <geom class="drawer_col" pos="0 0.092 -0.008" size="0.098 0.008 0.076" type="box"/>
                    <geom class="drawer_col" pos="0 -0.008 -0.07" size="0.098 0.092 0.014" type="box"/>
                    <geom class="drawer_col" pos="0 0 0.076" size="0.098 0.1 0.008" type="box"/>
                    <body name="drawer_link_1" pos="0 -0.01 0.006">
                        <joint type="slide" range="-0.16 0" axis="0 1 0" name="goal_1_slidey" pos="0 0 0" damping="2"
                               limited="true"/>
                        <geom class="drawer_col" pos="0 -0.082 0.008" size="0.09 0.008 0.052" type="box" mass=".04"/>
                        <geom class="drawer_col" pos="0 0.082 0.008" size="0.09 0.008 0.052" type="box" mass=".04"/>
                        <geom class="drawer_col" pos="-0.082 0 0.008" size="0.007 0.074 0.052" type="box" mass=".04"/>
                        <geom class="drawer_col" pos="0.082 0 0.008" size="0.007 0.074 0.052" type="box" mass=".04"/>
                        <geom class="drawer_col" pos="0 0 -0.052" size="0.09 0.09 0.008" type="box" mass=".04"/>
                        <geom class="drawer_col" euler="1.571 0 0" pos="-0.04 -0.12 0.04" size="0.009 0.05"
                              type="capsule" mass=".06"/>
                        <geom class="drawer_col" euler="0 1.57 0" pos="0 -0.17 0.04" size="0.009 0.04" type="capsule"
                              mass=".06"/>
                        <geom class="drawer_col" euler="1.57 0 0" pos="0.04 -0.12 0.04" size="0.009 0.05" type="capsule"
                              mass=".06"/>
                        <body name="handle_pos_1" pos="0 -0.17 0.04">
                            <geom name='handle_1' class="drawer_col" size="0.01" rgba="1 0 0 0" type="sphere"/>
                        </body>
                        <site name="goal1" size="0.01" rgba="1 0 0 1" pos="0 -0.17 0.04"/>
                    </body>

                </body>
                <body name="drawer_case2" pos="0.10 0 0.084">
                    <geom class="drawer_col" pos="-0.09 0 0" size="0.008 0.1 0.084" type="box"/>
                    <geom class="drawer_col" pos="0.09 0 0" size="0.008 0.1 0.084" type="box"/>
                    <geom class="drawer_col" pos="0 0.092 -0.008" size="0.098 0.008 0.076" type="box"/>
                    <geom class="drawer_col" pos="0 -0.008 -0.07" size="0.098 0.092 0.014" type="box"/>
                    <geom class="drawer_col" pos="0 0 0.076" size="0.098 0.1 0.008" type="box"/>
                    <body name="drawer_link_2" pos="0 -0.01 0.006">
                        <joint type="slide" range="-0.16 0" axis="0 1 0" name="goal_2_slidey" pos="0 0 0" damping="2"
                               limited="true"/>
                        <geom class="drawer_col" pos="0 -0.082 0.008" size="0.09 0.008 0.052" type="box" mass=".04"/>
                        <geom class="drawer_col" pos="0 0.082 0.008" size="0.09 0.008 0.052" type="box" mass=".04"/>
                        <geom class="drawer_col" pos="-0.082 0 0.008" size="0.007 0.074 0.052" type="box" mass=".04"/>
                        <geom class="drawer_col" pos="0.082 0 0.008" size="0.007 0.074 0.052" type="box" mass=".04"/>
                        <geom class="drawer_col" pos="0 0 -0.052" size="0.09 0.09 0.008" type="box" mass=".04"/>
                        <geom class="drawer_col" euler="1.571 0 0" pos="-0.04 -0.12 0.04" size="0.009 0.05"
                              type="capsule" mass=".06"/>
                        <geom class="drawer_col" euler="0 1.57 0" pos="0 -0.17 0.04" size="0.009 0.04" type="capsule"
                              mass=".06"/>
                        <geom class="drawer_col" euler="1.57 0 0" pos="0.04 -0.12 0.04" size="0.009 0.05" type="capsule"
                              mass=".06"/>
                        <body name="handle_pos_2" pos="0 -0.17 0.04">
                            <geom name='handle_2' class="drawer_col" size="0.01" rgba="1 0 0 0" type="sphere"/>
                        </body>
                        <site name="goal2" size="0.01" rgba="1 0 0 1" pos="0 -0.17 0.04"/>
                    </body>
                </body>
            </body>
            <site rgba="0 0 0 0" size="0.0005" pos="0 0 -0.08" name="bottom_site"/>
            <site rgba="0 0 0 0" size="0.0005" pos="0 0 0.65" name="top_site"/>
            <site rgba="0 0 0 0" size="0.0005" pos="0.011 0.09 0" name="horizontal_radius_site"/>
        </body>
    </worldbody>
</mujoco>
