<mujoco model="hammerblock">
    <compiler angle="radian" inertiafromgeom="auto" inertiagrouprange="4 5"/>
    <asset>
        <texture name="T_hmr_met" type="cube" file="textures/metal1.png"/>
        <texture name="T_hmr_wood" type="cube" file="textures/wood1.png"/>

        <material name="hmr_col" texture="T_hmr_wood" reflectance="0.7" texrepeat="5 5" texuniform="true"/>
        <material name="hmr_red" rgba=".65 0 0 1" shininess="1" reflectance=".7" specular=".5"/>
        <material name="hmr_metal" texture="T_hmr_met" rgba=".65 .65 .65 1" shininess="1" reflectance=".7"
                  specular=".5"/>
        <material name="hmr_wood" texture="T_hmr_wood" shininess="1" reflectance=".7" specular=".5"/>
        <mesh file="meshes/hammer/hammerblock.stl" name="hammerblock"/>
        <mesh file="meshes/hammer/nail.stl" name="nail"/>
        <mesh file="meshes/hammer/hammerhandle.stl" name="hammerhandle"/>
    </asset>
    <default>

        <default class="hmr_base">
            <joint armature="0.001" damping="2" limited="true"/>
            <geom conaffinity="0" contype="0" group="1" type="mesh"/>
            <position ctrllimited="true" ctrlrange="0 1.57"/>
            <default class="hmr_viz">
                <geom condim="4" type="mesh"/>
            </default>
            <default class="hmr_col">
                <geom conaffinity="1" condim="3" contype="1" group="1" material="hmr_col" solimp="0.99 0.99 0.01"
                      solref="0.01 1"/>
            </default>
        </default>
    </default>

    <worldbody>
        <body childclass="hmr_base">
            <body name="object">
                <geom class="hmr_col" pos="0 0 0.172" size="0.1 0.1 0.048" type="box"/>
                <geom class="hmr_col" pos="0.058 0 0.11" size="0.042 0.1 0.014" type="box"/>
                <geom class="hmr_col" pos="-0.058 0 0.11" size="0.042 0.1 0.014" type="box"/>
                <geom class="hmr_col" pos="0 0 0.048" size="0.1 0.1 0.048" type="box"/>
                <body name="nail_link_1" pos="0 -0.21 0.05">
                    <joint type="slide" axis="0 1 0" range="0 .05" name="NailSlideJoint_1" damping="2"/>
                    <geom class="hmr_col" euler="1.57 0 0" pos="0.0 0.057 0" size="0.01 0.06" type="cylinder" material="hmr_metal"/>
                    <geom class="hmr_col" euler="1.57 0 0" size="0.025 0.009" type="cylinder" material="hmr_metal"/>
                </body>
                <body name="nail_link_2" pos="0 -0.21 0.14">
                    <joint type="slide" axis="0 1 0" range="0 .05" name="NailSlideJoint_2" damping="2"/>
                    <geom class="hmr_col" euler="1.57 0 0" pos="0.0 0.057 0" size="0.01 0.06" type="cylinder" material="hmr_metal"/>
                    <geom class="hmr_col" euler="1.57 0 0" size="0.025 0.009" type="cylinder" material="hmr_metal"/>
                </body>
            </body>
            <site rgba="0 0 0 0" size="0.0005" pos="0 0 -0.08" name="bottom_site"/>
            <site rgba="0 0 0 0" size="0.0005" pos="0 0 0.65" name="top_site"/>
            <site rgba="0 0 0 0" size="0.0005" pos="0.011 0.09 0" name="horizontal_radius_site"/>
        </body>
    </worldbody>
</mujoco>
